Workbook

Sheet Supuestos
A1: NOCTA — Supuestos del modelo financiero (España, 2026)
A2: Todas las celdas en azul son inputs editables. El resto de hojas referencia estos valores.
A4: Parámetro | B4: Valor | C4: Unidad | D4: Nota / fuente
A5: Cambio de divisa e impuestos
A6: Tipo de cambio USD → EUR | B6: 0.92 | C6: €/$ | D6: Supuesto dado en el encargo
A7: IVA España (tipo general) | B7: 0.21 | C7: % | D7: Ley 37/1992 IVA
A9: Shopify y pasarela de pago
A10: Shopify Basic | B10: 27 | C10: €/mes | D10: Supuesto dado (precio 2026)
A11: Shopify Grow (plan superior) | B11: 79 | C11: €/mes | D11: Supuesto dado (precio 2026)
A12: Comisión Shopify Payments | B12: 0.019 | C12: % s/venta | D12: Supuesto dado
A13: Fee fijo Shopify Payments | B13: 0.25 | C13: €/transacción | D13: Supuesto dado
A14: Comisión Klarna | B14: 0.0249 | C14: % s/venta | D14: Supuesto dado
A15: Fee fijo Klarna | B15: 0.35 | C15: €/transacción | D15: Supuesto dado
A17: Envío (Correos / GLS) — 250 g, según región
A18: Envío Península (mínimo) | B18: 3.5 | C18: € | D18: Supuesto dado
A19: Envío Península (máximo) | B19: 4.5 | C19: € | D19: Supuesto dado
A20: Envío Península (medio) | B20: =AVERAGE(B18:B19) -> 4 | C20: € | D20: Media del rango dado
A21: Envío Baleares | B21: 6 | C21: € | D21: Supuesto dado
A22: Envío Canarias | B22: 9 | C22: € | D22: Supuesto dado
A23: % pedidos Península | B23: 0.9 | C23: % | D23: Estimación: distribución de población/envíos España
A24: % pedidos Baleares | B24: 0.05 | C24: % | D24: Estimación
A25: % pedidos Canarias | B25: 0.05 | C25: % | D25: Estimación
A26: Envío medio ponderado (mix regional) | B26: =B20*B23+B21*B24+B22*B25 -> 4.35 | C26: € | D26: Ponderado por mix regional estimado
A28: Logística 3PL (pick&pack, packaging, devoluciones)
A29: Pick&pack 3PL (mínimo) | B29: 2.2 | C29: €/pedido | D29: Supuesto dado
A30: Pick&pack 3PL (máximo) | B30: 2.8 | C30: €/pedido | D30: Supuesto dado
A31: Pick&pack 3PL (medio) | B31: =AVERAGE(B29:B30) -> 2.5 | C31: €/pedido | D31: Media del rango dado
A32: Coste por unidad adicional en pedido | B32: 0.45 | C32: €/ud adicional | D32: Supuesto dado
A33: Packaging de envío (caja/sobre + relleno) | B33: 0.35 | C33: €/pedido | D33: Supuesto dado
A34: Tasa de devoluciones | B34: 0.03 | C34: % | D34: Supuesto dado
A36: Marketing / adquisición (Meta Ads)
A37: CPM Meta España (mínimo) | B37: 6 | C37: € | D37: Supuesto dado
A38: CPM Meta España (máximo) | B38: 9 | C38: € | D38: Supuesto dado
A39: CPM Meta España (medio) | B39: =AVERAGE(B37:B38) -> 7.5 | C39: € | D39: Media del rango dado
A40: CTR | B40: 0.012 | C40: % | D40: Supuesto dado
A41: CVR (escenario Base) | B41: 0.022 | C41: % | D41: Supuesto dado (base)
A42: CVR (escenario Conservador) | B42: 0.016 | C42: % | D42: Estimación: -27% vs. base por menor eficiencia de creatividades/audiencia
A43: CVR (escenario Agresivo) | B43: 0.028 | C43: % | D43: Estimación: +27% vs. base por buen product-market fit y UGC
A44: AOV (ticket medio, con IVA) | B44: 38 | C44: € | D44: Supuesto dado
A45: Unidades por pedido | B45: 1.6 | C45: uds | D45: Supuesto dado
...

Sheet Unit Economics SKU
A1: NOCTA — Unit economics por SKU (Corea vs. China)
A2: Costes de fábrica a nivel de pack completo (no por pieza individual). Los bundles suman el coste de sus componentes.
A4: SKU | B4: Tipo | C4: Uds/ pack | D4: PVP con IVA | E4: PVP sin IVA | F4: Coste KR mín ($) | G4: Coste KR máx ($) | H4: Coste KR medio ($) | I4: Coste CN mín ($) | J4: Coste CN máx ($) | K4: Coste CN medio ($) | L4: Packaging ($) | M4: Troquel ($) | N4: Flete (€) | O4: Desembar- cado KR (€) | P4: Desembar- cado CN (€) | Q4: Margen bruto KR (€) | R4: Margen bruto KR (%) | S4: Margen bruto CN (€) | T4: Margen bruto CN (%) | U4: Pasarela (€) | V4: Envío (€) | W4: Pick&pack (€) | X4: Pack. envío (€) | Y4: Devol. KR (€) | Z4: Margen contrib. KR (€) | AA4: Margen contrib. KR (%) | AB4: Devol. CN (€) | AC4: Margen contrib. CN (€) | AD4: Mix ventas (% pedidos)
A5: 1. Parches nariz (8 uds) | B5: Parche | C5: 8 | D5: 16.95 | E5: =D5/(1+Supuestos!$B$7) -> 14.008264 | F5: 2.4 | G5: 4.8 | H5: =AVERAGE(F5:G5) -> 3.6 | I5: 1.2 | J5: 1.68 | K5: =AVERAGE(I5:J5) -> 1.44 | L5: =Supuestos!$B$58 -> 0.55 | M5: =IF(B5="Parche",Supuestos!$B$61*C5,0) -> 2.6666667 | N5: =IF(B5="Parche",Supuestos!$B$62*C5,Supuestos!$B$62) -> 2.4 | O5: =(H5+L5+M5)*Supuestos!$B$6*(1+Supuestos!$B$63)+N5 -> 8.6713333 | P5: =(K5+L5+M5)*Supuestos!$B$6*(1+Supuestos!$B$64)+N5 -> 6.962602 | Q5: =E5-O5 -> 5.3369311 | R5: =Q5/E5 -> 0.38098446 | S5: =E5-P5 -> 7.0456625 | T5: =S5/E5 -> 0.50296469 | U5: =D5*Supuestos!$B$12+Supuestos!$B$13 -> 0.57205 | V5: =IF(D5>=Supuestos!$B$75,Supuestos!$B$26,0) -> 0 | W5: =Supuestos!$B$31 -> 2.5 | X5: =Supuestos!$B$33 -> 0.35 | Y5: =-Supuestos!$B$34*Q5 -> -0.16010793 | Z5: =Q5-U5-V5-W5-X5+Y5 -> 1.7547732 | AA5: =Z5/E5 -> 0.125267 | AB5: =-Supuestos!$B$34*S5 -> -0.21136987 | AC5: =S5-U5-V5-W5-X5+AB5 -> 3.4122426 | AD5: 0.22
A6: 2. Parches granos (36 pts) | B6: Parche | C6: 36 | D6: 15.95 | E6: =D6/(1+Supuestos!$B$7) -> 13.181818 | F6: 0.5 | G6: 0.75 | H6: =AVERAGE(F6:G6) -> 0.625 | I6: 0.9 | J6: 1.3 | K6: =AVERAGE(I6:J6) -> 1.1 | L6: =Supuestos!$B$58 -> 0.55 | M6: =IF(B6="Parche",Supuestos!$B$61*C6,0) -> 12 | N6: =IF(B6="Parche",Supuestos!$B$62*C6,Supuestos!$B$62) -> 10.8 | O6: =(H6+L6+M6)*Supuestos!$B$6*(1+Supuestos!$B$63)+N6 -> 22.921 | P6: =(K6+L6+M6)*Supuestos!$B$6*(1+Supuestos!$B$64)+N6 -> 24.17427 | Q6: =E6-O6 -> -9.7391818 | R6: =Q6/E6 -> -0.73883448 | S6: =E6-P6 -> -10.992452 | T6: =S6/E6 -> -0.83391014 | U6: =D6*Supuestos!$B$12+Supuestos!$B$13 -> 0.55305 | V6: =IF(D6>=Supuestos!$B$75,Supuestos!$B$26,0) -> 0 | W6: =Supuestos!$B$31 -> 2.5 | X6: =Supuestos!$B$33 -> 0.35 | Y6: =-Supuestos!$B$34*Q6 -> 0.29217545 | Z6: =Q6-U6-V6-W6-X6+Y6 -> -12.850056 | AA6: =Z6/E6 -> -0.97483186 | AB6: =-Supuestos!$B$34*S6 -> 0.32977355 | AC6: =S6-U6-V6-W6-X6+AB6 -> -14.065728 | AD6: 0.12
A7: 3. Parches superficie (10 uds) | B7: Parche | C7: 10 | D7: 15.95 | E7: =D7/(1+Supuestos!$B$7) -> 13.181818 | F7: 2 | G7: 4 | H7: =AVERAGE(F7:G7) -> 3 | I7: 1.3 | J7: 2 | K7: =AVERAGE(I7:J7) -> 1.65 | L7: =Supuestos!$B$58 -> 0.55 | M7: =IF(B7="Parche",Supuestos!$B$61*C7,0) -> 3.3333333 | N7: =IF(B7="Parche",Supuestos!$B$62*C7,Supuestos!$B$62) -> 3 | O7: =(H7+L7+M7)*Supuestos!$B$6*(1+Supuestos!$B$63)+N7 -> 9.3326667 | P7: =(K7+L7+M7)*Supuestos!$B$6*(1+Supuestos!$B$64)+N7 -> 8.42156 | Q7: =E7-O7 -> 3.8491515 | R7: =Q7/E7 -> 0.2920046 | S7: =E7-P7 -> 4.7602582 | T7: =S7/E7 -> 0.36112303 | U7: =D7*Supuestos!$B$12+Supuestos!$B$13 -> 0.55305 | V7: =IF(D7>=Supuestos!$B$75,Supuestos!$B$26,0) -> 0 | W7: =Supuestos!$B$31 -> 2.5 | X7: =Supuestos!$B$33 -> 0.35 | Y7: =-Supuestos!$B$34*Q7 -> -0.11547455 | Z7: =Q7-U7-V7-W7-X7+Y7 -> 0.33062697 | AA7: =Z7/E7 -> 0.025082046 | AB7: =-Supuestos!$B$34*S7 -> -0.14280775 | AC7: =S7-U7-V7-W7-X7+AB7 -> 1.2144004 | AD7: 0.08
A8: 4. Parches barbilla (8 uds) | B8: Parche | C8: 8 | D8: 16.95 | E8: =D8/(1+Supuestos!$B$7) -> 14.008264 | F8: 2.4 | G8: 4.8 | H8: =AVERAGE(F8:G8) -> 3.6 | I8: 1.2 | J8: 1.68 | K8: =AVERAGE(I8:J8) -> 1.44 | L8: =Supuestos!$B$58 -> 0.55 | M8: =IF(B8="Parche",Supuestos!$B$61*C8,0) -> 2.6666667 | N8: =IF(B8="Parche",Supuestos!$B$62*C8,Supuestos!$B$62) -> 2.4 | O8: =(H8+L8+M8)*Supuestos!$B$6*(1+Supuestos!$B$63)+N8 -> 8.6713333 | P8: =(K8+L8+M8)*Supuestos!$B$6*(1+Supuestos!$B$64)+N8 -> 6.962602 | Q8: =E8-O8 -> 5.3369311 | R8: =Q8/E8 -> 0.38098446 | S8: =E8-P8 -> 7.0456625 | T8: =S8/E8 -> 0.50296469 | U8: =D8*Supuestos!$B$12+Supuestos!$B$13 -> 0.57205 | V8: =IF(D8>=Supuestos!$B$75,Supuestos!$B$26,0) -> 0 | W8: =Supuestos!$B$31 -> 2.5 | X8: =Supuestos!$B$33 -> 0.35 | Y8: =-Supuestos!$B$34*Q8 -> -0.16010793 | Z8: =Q8-U8-V8-W8-X8+Y8 -> 1.7547732 | AA8: =Z8/E8 -> 0.125267 | AB8: =-Supuestos!$B$34*S8 -> -0.21136987 | AC8: =S8-U8-V8-W8-X8+AB8 -> 3.4122426 | AD8: 0.06
A9: 5. Parches frente (5 uds) | B9: Parche | C9: 5 | D9: 16.95 | E9: =D9/(1+Supuestos!$B$7) -> 14.008264 | F9: 1.5 | G9: 3 | H9: =AVERAGE(F9:G9) -> 2.25 | I9: 0.75 | J9: 1.05 | K9: =AVERAGE(I9:J9) -> 0.9 | L9: =Supuestos!$B$58 -> 0.55 | M9: =IF(B9="Parche",Supuestos!$B$61*C9,0) -> 1.6666667 | N9: =IF(B9="Parche",Supuestos!$B$62*C9,Supuestos!$B$62) -> 1.5 | O9: =(H9+L9+M9)*Supuestos!$B$6*(1+Supuestos!$B$63)+N9 -> 5.6093333 | P9: =(K9+L9+M9)*Supuestos!$B$6*(1+Supuestos!$B$64)+N9 -> 4.55371 | Q9: =E9-O9 -> 8.3989311 | R9: =Q9/E9 -> 0.59956971 | S9: =E9-P9 -> 9.4545545 | T9: =S9/E9 -> 0.6749269 | U9: =D9*Supuestos!$B$12+Supuestos!$B$13 -> 0.57205 | V9: =IF(D9>=Supuestos!$B$75,Supuestos!$B$26,0) -> 0 | W9: =Supuestos!$B$31 -> 2.5 | X9: =Supuestos!$B$33 -> 0.35 | Y9: =-Supuestos!$B$34*Q9 -> -0.25196793 | Z9: =Q9-U9-V9-W9-X9+Y9 -> 4.7249132 | AA9: =Z9/E9 -> 0.33729469 | AB9: =-Supuestos!$B$34*S9 -> -0.28363663 | AC9: =S9-U9-V9-W9-X9+AB9 -> 5.7488678 | AD9: 0.06
A10: 6. Exfoliante salicílico 2% 110ml | B10: Líquido | C10: 1 | D10: 32 | E10: =D10/(1+Supuestos!$B$7) -> 26.446281 | F10: 2 | G10: 5 | H10: =AVERAGE(F10:G10) -> 3.5 | I10: 1 | J10: 2.5 | K10: =AVERAGE(I10:J10) -> 1.75 | L10: =Supuestos!$B$58 -> 0.55 | M10: =IF(B10="Parche",Supuestos!$B$61*C10,0) -> 0 | N10: =IF(B10="Parche",Supuestos!$B$62*C10,Supuestos!$B$62) -> 0.3 | O10: =(H10+L10+M10)*Supuestos!$B$6*(1+Supuestos!$B$63)+N10 -> 4.026 | P10: =(K10+L10+M10)*Supuestos!$B$6*(1+Supuestos!$B$64)+N10 -> 2.55354 | Q10: =E10-O10 -> 22.420281 | R10: =Q10/E10 -> 0.84776688 | S10: =E10-P10 -> 23.892741 | T10: =S10/E10 -> 0.90344427 | U10: =D10*Supuestos!$B$12+Supuestos!$B$13 -> 0.858 | V10: =IF(D10>=Supuestos!$B$75,Supuestos!$B$26,0) -> 4.35 | W10: =Supuestos!$B$31 -> 2.5 | X10: =Supuestos!$B$33 -> 0.35 | Y10: =-Supuestos!$B$34*Q10 -> -0.67260843 | Z10: =Q10-U10-V10-W10-X10+Y10 -> 13.689673 | AA10: =Z10/E10 -> 0.51764074 | AB10: =-Supuestos!$B$34*S10 -> -0.71678223 | AC10: =S10-U10-V10-W10-X10+AB10 -> 15.117959 | AD10: 0.1
A11: 7. Sérum niacinamida 30ml | B11: Líquido | C11: 1 | D11: 29 | E11: =D11/(1+Supuestos!$B$7) -> 23.966942 | F11: 2.5 | G11: 5.5 | H11: =AVERAGE(F11:G11) -> 4 | I11: 1 | J11: 1.6 | K11: =AVERAGE(I11:J11) -> 1.3 | L11: =Supuestos!$B$58 -> 0.55 | M11: =IF(B11="Parche",Supuestos!$B$61*C11,0) -> 0 | N11: =IF(B11="Parche",Supuestos!$B$62*C11,Supuestos!$B$62) -> 0.3 | O11: =(H11+L11+M11)*Supuestos!$B$6*(1+Supuestos!$B$63)+N11 -> 4.486 | P11: =(K11+L11+M11)*Supuestos!$B$6*(1+Supuestos!$B$64)+N11 -> 2.11263 | Q11: =E11-O11 -> 19.480942 | R11: =Q11/E11 -> 0.81282552 | S11: =E11-P11 -> 21.854312 | T11: =S11/E11 -> 0.91185233 | U11: =D11*Supuestos!$B$12+Supuestos!$B$13 -> 0.801 | V11: =IF(D11>=Supuestos!$B$75,Supuestos!$B$26,0) -> 0 | W11: =Supuestos!$B$31 -> 2.5 | X11: =Supuestos!$B$33 -> 0.35 | Y11: =-Supuestos!$B$34*Q11 -> -0.58442826 | Z11: =Q11-U11-V11-W11-X11+Y11 -> 15.245514 | AA11: =Z11/E11 -> 0.63610592 | AB11: =-Supuestos!$B$34*S11 -> -0.65562936 | AC11: =S11-U11-V11-W11-X11+AB11 -> 17.547683 | AD11: 0.1
A12: 8. Peel-off colágeno 70ml | B12: Líquido | C12: 1 | D12: 29 | E12: =D12/(1+Supuestos!$B$7) -> 23.966942 | F12: 2 | G12: 4 | H12: =AVERAGE(F12:G12) -> 3 | I12: 1 | J12: 2 | K12: =AVERAGE(I12:J12) -> 1.5 | L12: =Supuestos!$B$58 -> 0.55 | M12: =IF(B12="Parche",Supuestos!$B$61*C12,0) -> 0 | N12: =IF(B12="Parche",Supuestos!$B$62*C12,Supuestos!$B$62) -> 0.3 | O12: =(H12+L12+M12)*Supuestos!$B$6*(1+Supuestos!$B$63)+N12 -> 3.566 | P12: =(K12+L12+M12)*Supuestos!$B$6*(1+Supuestos!$B$64)+N12 -> 2.30859 | Q12: =E12-O12 -> 20.400942 | R12: =Q12/E12 -> 0.85121172 | S12: =E12-P12 -> 21.658352 | T12: =S12/E12 -> 0.90367607 | U12: =D12*Supuestos!$B$12+Supuestos!$B$13 -> 0.801 | V12: =IF(D12>=Supuestos!$B$75,Supuestos!$B$26,0) -> 0 | W12: =Supuestos!$B$31 -> 2.5 | X12: =Supuestos!$B$33 -> 0.35 | Y12: =-Supuestos!$B$34*Q12 -> -0.61202826 | Z12: =Q12-U12-V12-W12-X12+Y12 -> 16.137914 | AA12: =Z12/E12 -> 0.67334054 | AB12: =-Supuestos!$B$34*S12 -> -0.64975056 | AC12: =S12-U12-V12-W12-X12+AB12 -> 17.357602 | AD12: 0.08
A13: 9. Pack 4 sheet masks | B13: Líquido | C13: 4 | D13: 15 | E13: =D13/(1+Supuestos!$B$7) -> 12.396694 | F13: 2 | G13: 8 | H13: =AVERAGE(F13:G13) -> 5 | I13: 0.6 | J13: 1.6 | K13: =AVERAGE(I13:J13) -> 1.1 | L13: =Supuestos!$B$58 -> 0.55 | M13: =IF(B13="Parche",Supuestos!$B$61*C13,0) -> 0 | N13: =IF(B13="Parche",Supuestos!$B$62*C13,Supuestos!$B$62) -> 0.3 | O13: =(H13+L13+M13)*Supuestos!$B$6*(1+Supuestos!$B$63)+N13 -> 5.406 | P13: =(K13+L13+M13)*Supuestos!$B$6*(1+Supuestos!$B$64)+N13 -> 1.91667 | Q13: =E13-O13 -> 6.9906942 | R13: =Q13/E13 -> 0.563916 | S13: =E13-P13 -> 10.480024 | T13: =S13/E13 -> 0.84538862 | U13: =D13*Supuestos!$B$12+Supuestos!$B$13 -> 0.535 | V13: =IF(D13>=Supuestos!$B$75,Supuestos!$B$26,0) -> 0 | W13: =Supuestos!$B$31 -> 2.5 | X13: =Supuestos!$B$33 -> 0.35 | Y13: =-Supuestos!$B$34*Q13 -> -0.20972083 | Z13: =Q13-U13-V13-W13-X13+Y13 -> 3.3959734 | AA13: =Z13/E13 -> 0.27394185 | AB13: =-Supuestos!$B$34*S13 -> -0.31440073 | AC13: =S13-U13-V13-W13-X13+AB13 -> 6.7806235 | AD13: 0.06
A14: 10. Tónico hialurónico 130ml | B14: Líquido | C14: 1 | D14: 25 | E14: =D14/(1+Supuestos!$B$7) -> 20.661157 | F14: 1.5 | G14: 5 | H14: =AVERAGE(F14:G14) -> 3.25 | I14: 0.8 | J14: 2 | K14: =AVERAGE(I14:J14) -> 1.4 | L14: =Supuestos!$B$58 -> 0.55 | M14: =IF(B14="Parche",Supuestos!$B$61*C14,0) -> 0 | N14: =IF(B14="Parche",Supuestos!$B$62*C14,Supuestos!$B$62) -> 0.3 | O14: =(H14+L14+M14)*Supuestos!$B$6*(1+Supuestos!$B$63)+N14 -> 3.796 | P14: =(K14+L14+M14)*Supuestos!$B$6*(1+Supuestos!$B$64)+N14 -> 2.21061 | Q14: =E14-O14 -> 16.865157 | R14: =Q14/E14 -> 0.8162736 | S14: =E14-P14 -> 18.450547 | T14: =S14/E14 -> 0.89300648 | U14: =D14*Supuestos!$B$12+Supuestos!$B$13 -> 0.725 | V14: =IF(D14>=Supuestos!$B$75,Supuestos!$B$26,0) -> 0 | W14: =Supuestos!$B$31 -> 2.5 | X14: =Supuestos!$B$33 -> 0.35 | Y14: =-Supuestos!$B$34*Q14 -> -0.50595471 | Z14: =Q14-U14-V14-W14-X14+Y14 -> 12.784202 | AA14: =Z14/E14 -> 0.61875539 | AB14: =-Supuestos!$B$34*S14 -> -0.55351641 | AC14: =S14-U14-V14-W14-X14+AB14 -> 14.322031 | AD14: 0.06
A15: Bundle Duo (nariz + exfoliante) | B15: Bundle | C15: 1 | D15: 44 | E15: =D15/(1+Supuestos!$B$7) -> 36.363636 | F15: n/a (suma componentes) | G15: n/a | H15: =H5+H10 -> 7.1 | I15: n/a | J15: n/a | K15: =K5+K10 -> 3.19 | L15: =Supuestos!$B$58 -> 0.55 | M15: =M5+M10 -> 2.6666667 | N15: =N5+N10 -> 2.7 | O15: =(H15+L15+M15)*Supuestos!$B$6*(1+Supuestos!$B$63)+N15 -> 12.191333 | P15: =(K15+L15+M15)*Supuestos!$B$6*(1+Supuestos!$B$64)+N15 -> 8.977252 | Q15: =E15-O15 -> 24.172303 | R15: =Q15/E15 -> 0.66473833 | S15: =E15-P15 -> 27.386384 | T15: =S15/E15 -> 0.75312557 | U15: =D15*Supuestos!$B$12+Supuestos!$B$13 -> 1.086 | V15: =IF(D15>=Supuestos!$B$75,Supuestos!$B$26,0) -> 4.35 | W15: =Supuestos!$B$31 -> 2.5 | X15: =Supuestos!$B$33 -> 0.35 | Y15: =-Supuestos!$B$34*Q15 -> -0.72516909 | Z15: =Q15-U15-V15-W15-X15+Y15 -> 15.161134 | AA15: =Z15/E15 -> 0.41693118 | AB15: =-Supuestos!$B$34*S15 -> -0.82159153 | AC15: =S15-U15-V15-W15-X15+AB15 -> 18.278793 | AD15: 0.03
A16: Bundle T-Zone (frente + nariz + barbilla) | B16: Bundle | C16: 1 | D16: 44 | E16: =D16/(1+Supuestos!$B$7) -> 36.363636 | F16: n/a (suma componentes) | G16: n/a | H16: =H9+H5+H8 -> 9.45 | I16: n/a | J16: n/a | K16: =K9+K5+K8 -> 3.78 | L16: =Supuestos!$B$58 -> 0.55 | M16: =M9+M5+M8 -> 7 | N16: =N9+N5+N8 -> 6.3 | O16: =(H16+L16+M16)*Supuestos!$B$6*(1+Supuestos!$B$63)+N16 -> 21.94 | P16: =(K16+L16+M16)*Supuestos!$B$6*(1+Supuestos!$B$64)+N16 -> 17.401134 | Q16: =E16-O16 -> 14.423636 | R16: =Q16/E16 -> 0.39665 | S16: =E16-P16 -> 18.962502 | T16: =S16/E16 -> 0.52146881 | U16: =D16*Supuestos!$B$12+Supuestos!$B$13 -> 1.086 | V16: =IF(D16>=Supuestos!$B$75,Supuestos!$B$26,0) -> 4.35 | W16: =Supuestos!$B$31 -> 2.5 | X16: =Supuestos!$B$33 -> 0.35 | Y16: =-Supuestos!$B$34*Q16 -> -0.43270909 | Z16: =Q16-U16-V16-W16-X16+Y16 -> 5.7049273 | AA16: =Z16/E16 -> 0.1568855 | AB16: =-Supuestos!$B$34*S16 -> -0.56887507 | AC16: =S16-U16-V16-W16-X16+AB16 -> 10.107627 | AD16: 0.02
A17: Bundle Full Face (nariz+superficie+barbilla+frente+granos) | B17: Bundle | C17: 1 | D17: 69 | E17: =D17/(1+Supuestos!$B$7) -> 57.024793 | F17: n/a (suma componentes) | G17: n/a | H17: =H5+H7+H8+H9+H6 -> 13.075 | I17: n/a | J17: n/a | K17: =K5+K7+K8+K9+K6 -> 6.53 | L17: =Supuestos!$B$58 -> 0.55 | M17: =M5+M7+M8+M9+M6 -> 22.333333 | N17: =N5+N7+N8+N9+N6 -> 20.1 | O17: =(H17+L17+M17)*Supuestos!$B$6*(1+Supuestos!$B$63)+N17 -> 53.181667 | P17: =(K17+L17+M17)*Supuestos!$B$6*(1+Supuestos!$B$64)+N17 -> 48.919184 | Q17: =E17-O17 -> 3.8431267 | R17: =Q17/E17 -> 0.067393961 | S17: =E17-P17 -> 8.1056094 | T17: =S17/E17 -> 0.14214185 | U17: =D17*Supuestos!$B$12+Supuestos!$B$13 -> 1.561 | V17: =IF(D17>=Supuestos!$B$75,Supuestos!$B$26,0) -> 4.35 | W17: =Supuestos!$B$31 -> 2.5 | X17: =Supuestos!$B$33 -> 0.35 | Y17: =-Supuestos!$B$34*Q17 -> -0.1152938 | Z17: =Q17-U17-V17-W17-X17+Y17 -> -5.0331671 | AA17: =Z17/E17 -> -0.088262785 | AB17: =-Supuestos!$B$34*S17 -> -0.24316828 | AC17: =S17-U17-V17-W17-X17+AB17 -> -0.89855889 | AD17: 0.01
A19: MEDIA PONDERADA POR MIX DE VENTAS | D19: =SUMPRODUCT(AD5:AD17,D5:D17)/SUM(AD5:AD17) -> 22.663 | E19: =SUMPRODUCT(AD5:AD17,E5:E17)/SUM(AD5:AD17) -> 18.729752 | O19: =SUMPRODUCT(AD5:AD17,O5:O17)/SUM(AD5:AD17) -> 9.2866233 | U19: =SUMPRODUCT(AD5:AD17,U5:U17)/SUM(AD5:AD17) -> 0.680597 | V19: =SUMPRODUCT(AD5:AD17,V5:V17)/SUM(AD5:AD17) -> 0.696 | W19: =SUMPRODUCT(AD5:AD17,W5:W17)/SUM(AD5:AD17) -> 2.5 | X19: =SUMPRODUCT(AD5:AD17,X5:X17)/SUM(AD5:AD17) -> 0.35 | Y19: =SUMPRODUCT(AD5:AD17,Y5:Y17)/SUM(AD5:AD17) -> -0.28329386 | Z19: =SUMPRODUCT(AD5:AD17,Z5:Z17)/SUM(AD5:AD17) -> 4.9332379 | AD19: =SUM(AD5:AD17) -> 1

Sheet PyG 12 meses
A1: NOCTA — Cuenta de resultados (PyG) mensual, meses 1-12
A2: Importes en € con IVA salvo 'neto de IVA'. Todos los drivers (azul) están en Supuestos/Escenarios; aquí solo hay fórmulas.
A4: Concepto | B4: Total / Prom. año 1 | C4: Mes 1 | D4: Mes 2 | E4: Mes 3 | F4: Mes 4 | G4: Mes 5 | H4: Mes 6 | I4: Mes 7 | J4: Mes 8 | K4: Mes 9 | L4: Mes 10 | M4: Mes 11 | N4: Mes 12
A5: Adquisición, pedidos y suscripción
A6: CPA activo (€/pedido nuevo) | B6: =AVERAGE(C6:N6) -> 12.75 | C6: =IF(1>=6,Supuestos!$B$117,Supuestos!$B$116+(Supuestos!$B$117-Supuestos!$B$116)*(1-1)/5) -> 18 | D6: =IF(2>=6,Supuestos!$B$117,Supuestos!$B$116+(Supuestos!$B$117-Supuestos!$B$116)*(2-1)/5) -> 16.6 | E6: =IF(3>=6,Supuestos!$B$117,Supuestos!$B$116+(Supuestos!$B$117-Supuestos!$B$116)*(3-1)/5) -> 15.2 | F6: =IF(4>=6,Supuestos!$B$117,Supuestos!$B$116+(Supuestos!$B$117-Supuestos!$B$116)*(4-1)/5) -> 13.8 | G6: =IF(5>=6,Supuestos!$B$117,Supuestos!$B$116+(Supuestos!$B$117-Supuestos!$B$116)*(5-1)/5) -> 12.4 | H6: =IF(6>=6,Supuestos!$B$117,Supuestos!$B$116+(Supuestos!$B$117-Supuestos!$B$116)*(6-1)/5) -> 11 | I6: =IF(7>=6,Supuestos!$B$117,Supuestos!$B$116+(Supuestos!$B$117-Supuestos!$B$116)*(7-1)/5) -> 11 | J6: =IF(8>=6,Supuestos!$B$117,Supuestos!$B$116+(Supuestos!$B$117-Supuestos!$B$116)*(8-1)/5) -> 11 | K6: =IF(9>=6,Supuestos!$B$117,Supuestos!$B$116+(Supuestos!$B$117-Supuestos!$B$116)*(9-1)/5) -> 11 | L6: =IF(10>=6,Supuestos!$B$117,Supuestos!$B$116+(Supuestos!$B$117-Supuestos!$B$116)*(10-1)/5) -> 11 | M6: =IF(11>=6,Supuestos!$B$117,Supuestos!$B$116+(Supuestos!$B$117-Supuestos!$B$116)*(11-1)/5) -> 11 | N6: =IF(12>=6,Supuestos!$B$117,Supuestos!$B$116+(Supuestos!$B$117-Supuestos!$B$116)*(12-1)/5) -> 11
A7: Inversión en Ads (€) | B7: =SUM(C7:N7) -> 71396.705 | C7: =Supuestos!$B$47 -> 3000 | D7: =MIN(IF(C43>=Supuestos!$B$46,C7*(1+Supuestos!$B$120),C7),Supuestos!$B$121) -> 3000 | E7: =MIN(IF(D43>=Supuestos!$B$46,D7*(1+Supuestos!$B$120),D7),Supuestos!$B$121) -> 3000 | F7: =MIN(IF(E43>=Supuestos!$B$46,E7*(1+Supuestos!$B$120),E7),Supuestos!$B$121) -> 3000 | G7: =MIN(IF(F43>=Supuestos!$B$46,F7*(1+Supuestos!$B$120),F7),Supuestos!$B$121) -> 3600 | H7: =MIN(IF(G43>=Supuestos!$B$46,G7*(1+Supuestos!$B$120),G7),Supuestos!$B$121) -> 4320 | I7: =MIN(IF(H43>=Supuestos!$B$46,H7*(1+Supuestos!$B$120),H7),Supuestos!$B$121) -> 5184 | J7: =MIN(IF(I43>=Supuestos!$B$46,I7*(1+Supuestos!$B$120),I7),Supuestos!$B$121) -> 6220.8 | K7: =MIN(IF(J43>=Supuestos!$B$46,J7*(1+Supuestos!$B$120),J7),Supuestos!$B$121) -> 7464.96 | ... N7: =MIN(IF(M43>=Supuestos!$B$46,M7*(1+Supuestos!$B$120),M7),Supuestos!$B$121) -> 12899.451
A8: Pedidos nuevos (uds) | B8: =SUM(C8:N8) -> 6124.8996 | C8: =IFERROR(C7/C6,0) -> 166.66667 | D8: =IFERROR(D7/D6,0) -> 180.72289 | E8: =IFERROR(E7/E6,0) -> 197.36842 | F8: =IFERROR(F7/F6,0) -> 217.3913 | G8: =IFERROR(G7/G6,0) -> 290.32258 | H8: =IFERROR(H7/H6,0) -> 392.72727 | I8: =IFERROR(I7/I6,0) -> 471.27273 | J8: =IFERROR(J7/J6,0) -> 565.52727 | ... N8: =IFERROR(N7/N6,0) -> 1172.6774
A9: Nuevos suscriptores (uds) | B9: =SUM(C9:N9) -> 918.73494 | C9: =C8*Supuestos!$B$122 -> 25 | D9: =D8*Supuestos!$B$122 -> 27.108434 | E9: =E8*Supuestos!$B$122 -> 29.605263 | F9: =F8*Supuestos!$B$122 -> 32.608696 | G9: =G8*Supuestos!$B$122 -> 43.548387 | H9: =H8*Supuestos!$B$122 -> 58.909091 | I9: =I8*Supuestos!$B$122 -> 70.690909 | J9: =J8*Supuestos!$B$122 -> 84.829091 | ... N9: =N8*Supuestos!$B$122 -> 175.9016
A10: Suscriptores activos (stock) | B10: =N10 -> 485.24298 | C10: =0 -> 0 | D10: =C10*(1-Supuestos!$B$103)+C9 -> 25 | E10: =D10*(1-Supuestos!$B$103)+D9 -> 48.358434 | F10: =E10*(1-Supuestos!$B$103)+E9 -> 70.709932 | G10: =F10*(1-Supuestos!$B$103)+F9 -> 92.712138 | H10: =G10*(1-Supuestos!$B$103)+G9 -> 122.3537 | I10: =H10*(1-Supuestos!$B$103)+H9 -> 162.90974 | J10: =I10*(1-Supuestos!$B$103)+I9 -> 209.16419 | K10: =J10*(1-Supuestos!$B$103)+J9 -> 262.61865 | ... N10: =M10*(1-Supuestos!$B$103)+M9 -> 485.24298
A11: Pedidos de suscripción (uds) | B11: =SUM(C11:N11) -> 2202.5121 | C11: =C10 -> 0 | D11: =D10 -> 25 | E11: =E10 -> 48.358434 | F11: =F10 -> 70.709932 | G11: =G10 -> 92.712138 | H11: =H10 -> 122.3537 | I11: =I10 -> 162.90974 | J11: =J10 -> 209.16419 | ... N11: =N10 -> 485.24298
A12: Pedidos de recompra no-suscriptores (uds) | B12: =SUM(C12:N12) -> 671.63427 | C12: =0 -> 0 | D12: =0 -> 0 | E12: =0 -> 0 | F12: =C8*(1-Supuestos!$B$122)*Supuestos!$B$123 -> 35.416667 | G12: =D8*(1-Supuestos!$B$122)*Supuestos!$B$123 -> 38.403614 | H12: =E8*(1-Supuestos!$B$122)*Supuestos!$B$123 -> 41.940789 | I12: =F8*(1-Supuestos!$B$122)*Supuestos!$B$123 -> 46.195652 | J12: =G8*(1-Supuestos!$B$122)*Supuestos!$B$123 -> 61.693548 | K12: =H8*(1-Supuestos!$B$122)*Supuestos!$B$123 -> 83.454545 | L12: =I8*(1-Supuestos!$B$122)*Supuestos!$B$123 -> 100.14545 | M12: =J8*(1-Supuestos!$B$122)*Supuestos!$B$123 -> 120.17455 | N12: =K8*(1-Supuestos!$B$122)*Supuestos!$B$123 -> 144.20945
A13: Pedidos totales (uds) | B13: =SUM(C13:N13) -> 8999.046 | C13: =C8+C11+C12 -> 166.66667 | D13: =D8+D11+D12 -> 205.72289 | E13: =E8+E11+E12 -> 245.72685 | F13: =F8+F11+F12 -> 323.5179 | G13: =G8+G11+G12 -> 421.43833 | H13: =H8+H11+H12 -> 557.02177 | I13: =I8+I11+I12 -> 680.37812 | J13: =J8+J11+J12 -> 836.38501 | ... N13: =N8+N11+N12 -> 1802.1298
A14: AOV medio ponderado (€, con IVA) | B14: =AVERAGE(C14:N14) -> 36.802919 | C14: =IFERROR(((C8+C12)*Supuestos!$B$119+C11*Supuestos!$B$119*(1-Supuestos!$B$71))/C13,Supuestos!$B$119) -> 38 | D14: =IFERROR(((D8+D12)*Supuestos!$B$119+D11*Supuestos!$B$119*(1-Supuestos!$B$71))/D13,Supuestos!$B$119) -> 37.307321 | E14: =IFERROR(((E8+E12)*Supuestos!$B$119+E11*Supuestos!$B$119*(1-Supuestos!$B$71))/E13,Supuestos!$B$119) -> 36.878254 | F14: =IFERROR(((F8+F12)*Supuestos!$B$119+F11*Supuestos!$B$119*(1-Supuestos!$B$71))/F13,Supuestos!$B$119) -> 36.754175 | G14: =IFERROR(((G8+G12)*Supuestos!$B$119+G11*Supuestos!$B$119*(1-Supuestos!$B$71))/G13,Supuestos!$B$119) -> 36.746058 | H14: =IFERROR(((H8+H12)*Supuestos!$B$119+H11*Supuestos!$B$119*(1-Supuestos!$B$71))/H13,Supuestos!$B$119) -> 36.747955 | I14: =IFERROR(((I8+I12)*Supuestos!$B$119+I11*Supuestos!$B$119*(1-Supuestos!$B$71))/I13,Supuestos!$B$119) -> 36.635192 | J14: =IFERROR(((J8+J12)*Supuestos!$B$119+J11*Supuestos!$B$119*(1-Supuestos!$B$71))/J13,Supuestos!$B$119) -> 36.574537 | ... N14: =IFERROR(((N8+N12)*Supuestos!$B$119+N11*Supuestos!$B$119*(1-Supuestos!$B$71))/N13,Supuestos!$B$119) -> 36.465213
A15: Ingresos (ventas, con IVA) (€) | B15: =SUM(C15:N15) -> 329409.43 | C15: =C13*C14 -> 6333.3333 | D15: =D13*D14 -> 7674.9699 | E15: =E13*E14 -> 9061.9774 | F15: =F13*F14 -> 11890.634 | G15: =G13*G14 -> 15486.197 | H15: =H13*H14 -> 20469.411 | I15: =I13*I14 -> 24925.783 | J15: =J13*J14 -> 30590.394 | ... N15: =N13*N14 -> 65715.047
A16: Ingresos netos de IVA (€) | B16: =SUM(C16:N16) -> 272239.2 | C16: =C15/(1+Supuestos!$B$7) -> 5234.1598 | D16: =D15/(1+Supuestos!$B$7) -> 6342.9503 | E16: =E15/(1+Supuestos!$B$7) -> 7489.2375 | F16: =F15/(1+Supuestos!$B$7) -> 9826.97 | G16: =G15/(1+Supuestos!$B$7) -> 12798.51 | H16: =H15/(1+Supuestos!$B$7) -> 16916.869 | I16: =I15/(1+Supuestos!$B$7) -> 20599.821 | J16: =J15/(1+Supuestos!$B$7) -> 25281.318 | ... N16: =N15/(1+Supuestos!$B$7) -> 54309.956
A17: Costes variables
A18: COGS — coste desembarcado (€) | B18: =SUM(C18:N18) -> 133713.2 | C18: =C13*'Unit Economics SKU'!$O$19*Supuestos!$B$45 -> 2476.4329 | D18: =D13*'Unit Economics SKU'!$O$19*Supuestos!$B$45 -> 3056.7536 | E18: =E13*'Unit Economics SKU'!$O$19*Supuestos!$B$45 -> 3651.1564 | F18: =F13*'Unit Economics SKU'!$O$19*Supuestos!$B$45 -> 4807.0222 | G18: =G13*'Unit Economics SKU'!$O$19*Supuestos!$B$45 -> 6261.9825 | H18: =H13*'Unit Economics SKU'!$O$19*Supuestos!$B$45 -> 8276.5621 | I18: =I13*'Unit Economics SKU'!$O$19*Supuestos!$B$45 -> 10109.465 | J18: =J13*'Unit Economics SKU'!$O$19*Supuestos!$B$45 -> 12427.508 | ... N18: =N13*'Unit Economics SKU'!$O$19*Supuestos!$B$45 -> 26777.121
A19: Comisión pasarela de pago (€) | B19: =SUM(C19:N19) -> 8508.5406 | C19: =C13*(C14*Supuestos!$B$12+Supuestos!$B$13) -> 162 | D19: =D13*(D14*Supuestos!$B$12+Supuestos!$B$13) -> 197.25515 | E19: =E13*(E14*Supuestos!$B$12+Supuestos!$B$13) -> 233.60928 | F19: =F13*(F14*Supuestos!$B$12+Supuestos!$B$13) -> 306.80152 | G19: =G13*(G14*Supuestos!$B$12+Supuestos!$B$13) -> 399.59733 | H19: =H13*(H14*Supuestos!$B$12+Supuestos!$B$13) -> 528.17425 | I19: =I13*(I14*Supuestos!$B$12+Supuestos!$B$13) -> 643.68441 | J19: =J13*(J14*Supuestos!$B$12+Supuestos!$B$13) -> 790.31375 | ... N19: =N13*(N14*Supuestos!$B$12+Supuestos!$B$13) -> 1699.1183
A20: Envío a cliente (€) | B20: =SUM(C20:N20) -> 6263.336 | C20: =C13*'Unit Economics SKU'!$V$19 -> 116 | D20: =D13*'Unit Economics SKU'!$V$19 -> 143.18313 | E20: =E13*'Unit Economics SKU'!$V$19 -> 171.02589 | F20: =F13*'Unit Economics SKU'!$V$19 -> 225.16846 | G20: =G13*'Unit Economics SKU'!$V$19 -> 293.32108 | H20: =H13*'Unit Economics SKU'!$V$19 -> 387.68715 | I20: =I13*'Unit Economics SKU'!$V$19 -> 473.54317 | J20: =J13*'Unit Economics SKU'!$V$19 -> 582.12397 | ... N20: =N13*'Unit Economics SKU'!$V$19 -> 1254.2823
A21: Logística 3PL pick&pack (€) | B21: =SUM(C21:N21) -> 22497.615 | C21: =C13*'Unit Economics SKU'!$W$19 -> 416.66667 | D21: =D13*'Unit Economics SKU'!$W$19 -> 514.30723 | E21: =E13*'Unit Economics SKU'!$W$19 -> 614.31714 | F21: =F13*'Unit Economics SKU'!$W$19 -> 808.79476 | G21: =G13*'Unit Economics SKU'!$W$19 -> 1053.5958 | H21: =H13*'Unit Economics SKU'!$W$19 -> 1392.5544 | I21: =I13*'Unit Economics SKU'!$W$19 -> 1700.9453 | J21: =J13*'Unit Economics SKU'!$W$19 -> 2090.9625 | ... N21: =N13*'Unit Economics SKU'!$W$19 -> 4505.3245
A22: Packaging de envío (€) | B22: =SUM(C22:N22) -> 3149.6661 | C22: =C13*'Unit Economics SKU'!$X$19 -> 58.333333 | D22: =D13*'Unit Economics SKU'!$X$19 -> 72.003012 | E22: =E13*'Unit Economics SKU'!$X$19 -> 86.004399 | F22: =F13*'Unit Economics SKU'!$X$19 -> 113.23127 | G22: =G13*'Unit Economics SKU'!$X$19 -> 147.50342 | H22: =H13*'Unit Economics SKU'!$X$19 -> 194.95762 | I22: =I13*'Unit Economics SKU'!$X$19 -> 238.13234 | J22: =J13*'Unit Economics SKU'!$X$19 -> 292.73475 | ... N22: =N13*'Unit Economics SKU'!$X$19 -> 630.74542
A23: Devoluciones (impacto neto) (€) | B23: =SUM(C23:N23) -> 4078.9992 | C23: =-C13*'Unit Economics SKU'!$Y$19*Supuestos!$B$45 -> 75.54503 | D23: =-D13*'Unit Economics SKU'!$Y$19*Supuestos!$B$45 -> 93.248052 | E23: =-E13*'Unit Economics SKU'!$Y$19*Supuestos!$B$45 -> 111.38066 | F23: =-F13*'Unit Economics SKU'!$Y$19*Supuestos!$B$45 -> 146.64102 | G23: =-G13*'Unit Economics SKU'!$Y$19*Supuestos!$B$45 -> 191.02543 | H23: =-H13*'Unit Economics SKU'!$Y$19*Supuestos!$B$45 -> 252.48136 | I23: =-I13*'Unit Economics SKU'!$Y$19*Supuestos!$B$45 -> 308.39511 | J23: =-J13*'Unit Economics SKU'!$Y$19*Supuestos!$B$45 -> 379.10838 | ... N23: =-N13*'Unit Economics SKU'!$Y$19*Supuestos!$B$45 -> 816.85169
A24: Total costes variables (€) | B24: =SUM(C24:N24) -> 178211.36 | C24: =C18+C19+C20+C21+C22+C23 -> 3304.9779 | D24: =D18+D19+D20+D21+D22+D23 -> 4076.7502 | E24: =E18+E19+E20+E21+E22+E23 -> 4867.4938 | F24: =F18+F19+F20+F21+F22+F23 -> 6407.6593 | G24: =G18+G19+G20+G21+G22+G23 -> 8347.0256 | H24: =H18+H19+H20+H21+H22+H23 -> 11032.417 | I24: =I18+I19+I20+I21+I22+I23 -> 13474.165 | J24: =J18+J19+J20+J21+J22+J23 -> 16562.751 | ... N24: =N18+N19+N20+N21+N22+N23 -> 35683.443
A25: Margen bruto (€) | B25: =SUM(C25:N25) -> 138526 | C25: =C16-C18 -> 2757.7269 | D25: =D16-D18 -> 3286.1967 | E25: =E16-E18 -> 3838.0811 | F25: =F16-F18 -> 5019.9477 | G25: =G16-G18 -> 6536.5278 | H25: =H16-H18 -> 8640.3065 | I25: =I16-I18 -> 10490.356 | J25: =J16-J18 -> 12853.81 | ... N25: =N16-N18 -> 27532.835
A26: Margen bruto (%) | B26: =AVERAGE(C26:N26) -> 0.51141812 | C26: =IFERROR(C25/C16,0) -> 0.52687098 | D26: =IFERROR(D25/D16,0) -> 0.51808646 | E26: =IFERROR(E25/E16,0) -> 0.51247956 | F26: =IFERROR(F25/F16,0) -> 0.51083373 | G26: =IFERROR(G25/G16,0) -> 0.51072567 | H26: =IFERROR(H25/H16,0) -> 0.51075094 | I26: =IFERROR(I25/I16,0) -> 0.50924502 | J26: =IFERROR(J25/J16,0) -> 0.50843116 | ... N26: =IFERROR(N25/N16,0) -> 0.50695742
A27: Costes fijos
A28: Shopify (plan Basic) (€) | B28: =SUM(C28:N28) -> 324 | C28: =Supuestos!$B$10 -> 27 | D28: =Supuestos!$B$10 -> 27 | E28: =Supuestos!$B$10 -> 27 | F28: =Supuestos!$B$10 -> 27 | G28: =Supuestos!$B$10 -> 27 | H28: =Supuestos!$B$10 -> 27 | I28: =Supuestos!$B$10 -> 27 | J28: =Supuestos!$B$10 -> 27 | ... N28: =Supuestos!$B$10 -> 27
A29: Apps de Shopify (€) | B29: =SUM(C29:N29) -> 3000 | C29: =Supuestos!$B$79 -> 250 | D29: =Supuestos!$B$79 -> 250 | E29: =Supuestos!$B$79 -> 250 | F29: =Supuestos!$B$79 -> 250 | G29: =Supuestos!$B$79 -> 250 | H29: =Supuestos!$B$79 -> 250 | I29: =Supuestos!$B$79 -> 250 | J29: =Supuestos!$B$79 -> 250 | ... N29: =Supuestos!$B$79 -> 250
A30: Freelance diseño/soporte (€) | B30: =SUM(C30:N30) -> 9600 | C30: =Supuestos!$B$80 -> 800 | D30: =Supuestos!$B$80 -> 800 | E30: =Supuestos!$B$80 -> 800 | F30: =Supuestos!$B$80 -> 800 | G30: =Supuestos!$B$80 -> 800 | H30: =Supuestos!$B$80 -> 800 | I30: =Supuestos!$B$80 -> 800 | J30: =Supuestos!$B$80 -> 800 | ... N30: =Supuestos!$B$80 -> 800
A31: Salarios (€) | B31: =SUM(C31:N31) -> 0 | C31: =0 -> 0 | D31: =0 -> 0 | E31: =0 -> 0 | F31: =0 -> 0 | G31: =0 -> 0 | H31: =0 -> 0 | I31: =0 -> 0 | J31: =0 -> 0 | ... N31: =0 -> 0
A32: Legal / CPNP recurrente (€) | B32: =SUM(C32:N32) -> 1800 | C32: =Supuestos!$B$106 -> 150 | D32: =Supuestos!$B$106 -> 150 | E32: =Supuestos!$B$106 -> 150 | F32: =Supuestos!$B$106 -> 150 | G32: =Supuestos!$B$106 -> 150 | H32: =Supuestos!$B$106 -> 150 | I32: =Supuestos!$B$106 -> 150 | J32: =Supuestos!$B$106 -> 150 | ... N32: =Supuestos!$B$106 -> 150
A33: Gestoría / contabilidad (€) | B33: =SUM(C33:N33) -> 1440 | C33: =Supuestos!$B$107 -> 120 | D33: =Supuestos!$B$107 -> 120 | E33: =Supuestos!$B$107 -> 120 | F33: =Supuestos!$B$107 -> 120 | G33: =Supuestos!$B$107 -> 120 | H33: =Supuestos!$B$107 -> 120 | I33: =Supuestos!$B$107 -> 120 | J33: =Supuestos!$B$107 -> 120 | ... N33: =Supuestos!$B$107 -> 120
A34: Muestras I+D / calidad (€) | B34: =SUM(C34:N34) -> 960 | C34: =Supuestos!$B$108 -> 80 | D34: =Supuestos!$B$108 -> 80 | E34: =Supuestos!$B$108 -> 80 | F34: =Supuestos!$B$108 -> 80 | G34: =Supuestos!$B$108 -> 80 | H34: =Supuestos!$B$108 -> 80 | I34: =Supuestos!$B$108 -> 80 | J34: =Supuestos!$B$108 -> 80 | ... N34: =Supuestos!$B$108 -> 80
A35: Total costes fijos (€) | B35: =SUM(C35:N35) -> 17124 | C35: =SUM(C28:C34) -> 1427 | D35: =SUM(D28:D34) -> 1427 | E35: =SUM(E28:E34) -> 1427 | F35: =SUM(F28:F34) -> 1427 | G35: =SUM(G28:G34) -> 1427 | H35: =SUM(H28:H34) -> 1427 | I35: =SUM(I28:I34) -> 1427 | J35: =SUM(J28:J34) -> 1427 | ... N35: =SUM(N28:N34) -> 1427
A36: Resultado
A37: Margen de contribución (€) | B37: =SUM(C37:N37) -> 22631.134 | C37: =C16-C24-C7 -> -1070.8181 | D37: =D16-D24-D7 -> -733.79987 | E37: =E16-E24-E7 -> -378.25623 | F37: =F16-F24-F7 -> 419.31073 | G37: =G16-G24-G7 -> 851.48472 | H37: =H16-H24-H7 -> 1564.4517 | I37: =I16-I24-I7 -> 1941.6558 | J37: =J16-J24-J7 -> 2497.7663 | ... N37: =N16-N24-N7 -> 5727.0621
A38: Margen de contribución (%) | B38: =AVERAGE(C38:N38) -> 0.036786681 | C38: =IFERROR(C37/C16,0) -> -0.20458262 | D38: =IFERROR(D37/D16,0) -> -0.11568747 | E38: =IFERROR(E37/E16,0) -> -0.050506641 | F38: =IFERROR(F37/F16,0) -> 0.042669381 | G38: =IFERROR(G37/G16,0) -> 0.066529987 | H38: =IFERROR(H37/H16,0) -> 0.092478798 | I38: =IFERROR(I37/I16,0) -> 0.094255958 | J38: =IFERROR(J37/J16,0) -> 0.098798897 | ... N38: =IFERROR(N37/N16,0) -> 0.10545142
A39: EBITDA (€) | B39: =SUM(C39:N39) -> 5507.134 | C39: =C37-C35 -> -2497.8181 | D39: =D37-D35 -> -2160.7999 | E39: =E37-E35 -> -1805.2562 | F39: =F37-F35 -> -1007.6893 | G39: =G37-G35 -> -575.51528 | H39: =H37-H35 -> 137.45168 | I39: =I37-I35 -> 514.65583 | J39: =J37-J35 -> 1070.7663 | ... N39: =N37-N35 -> 4300.0621
A40: EBITDA (%) | B40: =AVERAGE(C40:N40) -> -0.071306529 | C40: =IFERROR(C39/C16,0) -> -0.47721473 | D40: =IFERROR(D39/D16,0) -> -0.34066164 | E40: =IFERROR(E39/E16,0) -> -0.24104673 | F40: =IFERROR(F39/F16,0) -> -0.10254323 | G40: =IFERROR(G39/G16,0) -> -0.044967365 | H40: =IFERROR(H39/H16,0) -> 0.0081251254 | I40: =IFERROR(I39/I16,0) -> 0.02498351 | J40: =IFERROR(J39/J16,0) -> 0.042354054 | ... N40: =IFERROR(N39/N16,0) -> 0.079176314
A41: EBITDA acumulado (€) | B41: =N41 -> 5507.134 | C41: =C39 -> -2497.8181 | D41: =C41+D39 -> -4658.618 | E41: =D41+E39 -> -6463.8742 | F41: =E41+F39 -> -7471.5635 | G41: =F41+G39 -> -8047.0788 | H41: =G41+H39 -> -7909.6271 | I41: =H41+I39 -> -7394.9713 | J41: =I41+J39 -> -6324.205 | K41: =J41+K39 -> -4563.7881 | ... N41: =M41+N39 -> 5507.134
...

Sheet Caja
A1: NOCTA — Tesorería mensual (Mes 0 = prelanzamiento)
A2: Mes 0 incluye la inversión inicial (legal, marca, web, muestras, troqueles) y el depósito del primer pedido de inventario.
A4: Concepto | B4: Total año 1 | C4: Mes 0 | D4: Mes 1 | E4: Mes 2 | F4: Mes 3 | G4: Mes 4 | H4: Mes 5 | I4: Mes 6 | J4: Mes 7 | K4: Mes 8 | L4: Mes 9 | M4: Mes 10 | N4: Mes 11 | O4: Mes 12
A5: Inversión inicial (Mes 0, pago único)
A6: Compliance PR/CPSR/CPNP (10 SKU) (€) | B6: =SUM(D6:O6) -> 0 | C6: =Supuestos!$B$83+Supuestos!$B$84*9 -> 13000 | D6: =0 -> 0 | E6: =0 -> 0 | F6: =0 -> 0 | G6: =0 -> 0 | H6: =0 -> 0 | I6: =0 -> 0 | J6: =0 -> 0 | K6: =0 -> 0 | ... O6: =0 -> 0
A7: Declaración AEMPS (€) | B7: =SUM(D7:O7) -> 0 | C7: =Supuestos!$B$85 -> 466 | D7: =0 -> 0 | E7: =0 -> 0 | F7: =0 -> 0 | G7: =0 -> 0 | H7: =0 -> 0 | I7: =0 -> 0 | J7: =0 -> 0 | K7: =0 -> 0 | ... O7: =0 -> 0
A8: Registro de marca EUIPO (€) | B8: =SUM(D8:O8) -> 0 | C8: =Supuestos!$B$86 -> 850 | D8: =0 -> 0 | E8: =0 -> 0 | F8: =0 -> 0 | G8: =0 -> 0 | H8: =0 -> 0 | I8: =0 -> 0 | J8: =0 -> 0 | K8: =0 -> 0 | ... O8: =0 -> 0
A9: Diseño de marca y packaging (€) | B9: =SUM(D9:O9) -> 0 | C9: =Supuestos!$B$87 -> 2000 | D9: =0 -> 0 | E9: =0 -> 0 | F9: =0 -> 0 | G9: =0 -> 0 | H9: =0 -> 0 | I9: =0 -> 0 | J9: =0 -> 0 | K9: =0 -> 0 | ... O9: =0 -> 0
A10: Web (Shopify + apps) (€) | B10: =SUM(D10:O10) -> 0 | C10: =Supuestos!$B$88 -> 1500 | D10: =0 -> 0 | E10: =0 -> 0 | F10: =0 -> 0 | G10: =0 -> 0 | H10: =0 -> 0 | I10: =0 -> 0 | J10: =0 -> 0 | K10: =0 -> 0 | ... O10: =0 -> 0
A11: Fotos y vídeo de producto (€) | B11: =SUM(D11:O11) -> 0 | C11: =Supuestos!$B$89 -> 2000 | D11: =0 -> 0 | E11: =0 -> 0 | F11: =0 -> 0 | G11: =0 -> 0 | H11: =0 -> 0 | I11: =0 -> 0 | J11: =0 -> 0 | K11: =0 -> 0 | ... O11: =0 -> 0
A12: Creadoras UGC (€) | B12: =SUM(D12:O12) -> 0 | C12: =Supuestos!$B$90*Supuestos!$B$91 -> 1500 | D12: =0 -> 0 | E12: =0 -> 0 | F12: =0 -> 0 | G12: =0 -> 0 | H12: =0 -> 0 | I12: =0 -> 0 | J12: =0 -> 0 | K12: =0 -> 0 | ... O12: =0 -> 0
A13: Muestras de sourcing (10 SKU) (€) | B13: =SUM(D13:O13) -> 0 | C13: =Supuestos!$B$92*10 -> 1000 | D13: =0 -> 0 | E13: =0 -> 0 | F13: =0 -> 0 | G13: =0 -> 0 | H13: =0 -> 0 | I13: =0 -> 0 | J13: =0 -> 0 | K13: =0 -> 0 | ... O13: =0 -> 0
A14: Troqueles personalizados (€) | B14: =SUM(D14:O14) -> 0 | C14: =Supuestos!$B$59*Supuestos!$B$93*Supuestos!$B$6 -> 3680 | D14: =0 -> 0 | E14: =0 -> 0 | F14: =0 -> 0 | G14: =0 -> 0 | H14: =0 -> 0 | I14: =0 -> 0 | J14: =0 -> 0 | K14: =0 -> 0 | ... O14: =0 -> 0
A15: Total inversión inicial (€) | B15: =SUM(D15:O15) -> 0 | C15: =SUM(C6:C14) -> 25996 | D15: =SUM(D6:D14) -> 0 | E15: =SUM(E6:E14) -> 0 | F15: =SUM(F6:F14) -> 0 | G15: =SUM(G6:G14) -> 0 | H15: =SUM(H6:H14) -> 0 | I15: =SUM(I6:I14) -> 0 | J15: =SUM(J6:J14) -> 0 | ... O15: =SUM(O6:O14) -> 0
A16: Inventario
A17: COGS del mes (de PyG) (€) | B17: =SUM(D17:O17) -> 133713.2 | C17: =0 -> 0 | D17: ='PyG 12 meses'!C18 -> 2476.4329 | E17: ='PyG 12 meses'!D18 -> 3056.7536 | F17: ='PyG 12 meses'!E18 -> 3651.1564 | G17: ='PyG 12 meses'!F18 -> 4807.0222 | H17: ='PyG 12 meses'!G18 -> 6261.9825 | I17: ='PyG 12 meses'!H18 -> 8276.5621 | J17: ='PyG 12 meses'!I18 -> 10109.465 | K17: ='PyG 12 meses'!J18 -> 12427.508 | ... O17: ='PyG 12 meses'!N18 -> 26777.121
A18: Inventario recibido (€, a coste desembarcado) | B18: =SUM(D18:O18) -> 181422.57 | C18: =0 -> 0 | D18: =Supuestos!$B$97 -> 9000 | E18: =D20 -> 0 | F18: =E20 -> 0 | G18: =F20 -> 10953.469 | H18: =G20 -> 0 | I18: =H20 -> 18785.947 | J18: =I20 -> 0 | K18: =J20 -> 30328.394 | L18: =K20 -> 0 | ... O18: =N20 -> 66677.683
A19: Días de cobertura de stock | B19: =SUM(D19:O19) -> 706.44987 | C19: =0 -> 0 | D19: =IFERROR((C23+D18)/(D17/30),999) -> 109.02779 | E19: =IFERROR((D23+E18)/(E17/30),999) -> 64.024465 | F19: =IFERROR((E23+F18)/(F17/30),999) -> 28.485333 | G19: =IFERROR((F23+G18)/(G17/30),999) -> 67.208715 | H19: =IFERROR((G23+H18)/(H17/30),999) -> 28.563338 | I19: =IFERROR((H23+I18)/(I17/30),999) -> 67.006332 | J19: =IFERROR((I23+J18)/(J17/30),999) -> 30.296877 | K19: =IFERROR((J23+K18)/(K17/30),999) -> 73.454233 | ... O19: =IFERROR((N23+O18)/(O17/30),999) -> 83.451644
A20: Pedido de reposición generado (€) | B20: =SUM(D20:O20) -> 172422.57 | C20: =0 -> 0 | D20: =IF(D19<Supuestos!$B$100,D17*Supuestos!$B$101/30,0) -> 0 | E20: =IF(E19<Supuestos!$B$100,E17*Supuestos!$B$101/30,0) -> 0 | F20: =IF(F19<Supuestos!$B$100,F17*Supuestos!$B$101/30,0) -> 10953.469 | G20: =IF(G19<Supuestos!$B$100,G17*Supuestos!$B$101/30,0) -> 0 | H20: =IF(H19<Supuestos!$B$100,H17*Supuestos!$B$101/30,0) -> 18785.947 | I20: =IF(I19<Supuestos!$B$100,I17*Supuestos!$B$101/30,0) -> 0 | J20: =IF(J19<Supuestos!$B$100,J17*Supuestos!$B$101/30,0) -> 30328.394 | K20: =IF(K19<Supuestos!$B$100,K17*Supuestos!$B$101/30,0) -> 0 | ... O20: =IF(O19<Supuestos!$B$100,O17*Supuestos!$B$101/30,0) -> 0
A21: Pago depósito 30% a proveedor (€) | B21: =SUM(D21:O21) -> 51726.771 | C21: =Supuestos!$B$97*Supuestos!$B$98 -> 2700 | D21: =D20*Supuestos!$B$98 -> 0 | E21: =E20*Supuestos!$B$98 -> 0 | F21: =F20*Supuestos!$B$98 -> 3286.0408 | G21: =G20*Supuestos!$B$98 -> 0 | H21: =H20*Supuestos!$B$98 -> 5635.7842 | I21: =I20*Supuestos!$B$98 -> 0 | J21: =J20*Supuestos!$B$98 -> 9098.5181 | K21: =K20*Supuestos!$B$98 -> 0 | ... O21: =O20*Supuestos!$B$98 -> 0
A22: Pago saldo 70% a proveedor (€) | B22: =SUM(D22:O22) -> 126995.8 | C22: =0 -> 0 | D22: =Supuestos!$B$97*Supuestos!$B$99 -> 6300 | E22: =D20*Supuestos!$B$99 -> 0 | F22: =E20*Supuestos!$B$99 -> 0 | G22: =F20*Supuestos!$B$99 -> 7667.4284 | H22: =G20*Supuestos!$B$99 -> 0 | I22: =H20*Supuestos!$B$99 -> 13150.163 | J22: =I20*Supuestos!$B$99 -> 0 | K22: =J20*Supuestos!$B$99 -> 21229.875 | L22: =K20*Supuestos!$B$99 -> 0 | ... O22: =N20*Supuestos!$B$99 -> 46674.378
A23: Inventario en balance, fin de mes (€) | B23: =O23 -> 47709.371 | C23: =0 -> 0 | D23: =C23+D18-D17 -> 6523.5671 | E23: =D23+E18-E17 -> 3466.8135 | F23: =E23+F18-F17 -> -184.34289 | G23: =F23+G18-G17 -> 5962.104 | H23: =G23+H18-H17 -> -299.87845 | I23: =H23+I18-I17 -> 10209.507 | J23: =I23+J18-J17 -> 100.04237 | K23: =J23+K18-K17 -> 18000.928 | ... O23: =N23+O18-O17 -> 47709.371
A24: Cobros y pagos operativos
A25: Cobros de clientes (Stripe, D+2) (€) | B25: =SUM(D25:O25) -> 325028.42 | C25: =0 -> 0 | D25: ='PyG 12 meses'!C15*(1-Supuestos!$B$102/30) -> 5911.1111 | E25: ='PyG 12 meses'!D15*(1-Supuestos!$B$102/30)+'PyG 12 meses'!C15*(Supuestos!$B$102/30) -> 7585.5274 | F25: ='PyG 12 meses'!E15*(1-Supuestos!$B$102/30)+'PyG 12 meses'!D15*(Supuestos!$B$102/30) -> 8969.5102 | G25: ='PyG 12 meses'!F15*(1-Supuestos!$B$102/30)+'PyG 12 meses'!E15*(Supuestos!$B$102/30) -> 11702.057 | H25: ='PyG 12 meses'!G15*(1-Supuestos!$B$102/30)+'PyG 12 meses'!F15*(Supuestos!$B$102/30) -> 15246.493 | I25: ='PyG 12 meses'!H15*(1-Supuestos!$B$102/30)+'PyG 12 meses'!G15*(Supuestos!$B$102/30) -> 20137.197 | J25: ='PyG 12 meses'!I15*(1-Supuestos!$B$102/30)+'PyG 12 meses'!H15*(Supuestos!$B$102/30) -> 24628.692 | K25: ='PyG 12 meses'!J15*(1-Supuestos!$B$102/30)+'PyG 12 meses'!I15*(Supuestos!$B$102/30) -> 30212.754 | L25: ='PyG 12 meses'!K15*(1-Supuestos!$B$102/30)+'PyG 12 meses'!J15*(Supuestos!$B$102/30) -> 36985.132 | ... O25: ='PyG 12 meses'!N15*(1-Supuestos!$B$102/30)+'PyG 12 meses'!M15*(Supuestos!$B$102/30) -> 64972.072
A26: Pago costes variables no-COGS (€) | B26: =SUM(D26:O26) -> 40419.158 | C26: =0 -> 0 | D26: ='PyG 12 meses'!C19+'PyG 12 meses'!C20+'PyG 12 meses'!C21+'PyG 12 meses'!C22 -> 753 | E26: ='PyG 12 meses'!D19+'PyG 12 meses'!D20+'PyG 12 meses'!D21+'PyG 12 meses'!D22 -> 926.74852 | F26: ='PyG 12 meses'!E19+'PyG 12 meses'!E20+'PyG 12 meses'!E21+'PyG 12 meses'!E22 -> 1104.9567 | G26: ='PyG 12 meses'!F19+'PyG 12 meses'!F20+'PyG 12 meses'!F21+'PyG 12 meses'!F22 -> 1453.996 | H26: ='PyG 12 meses'!G19+'PyG 12 meses'!G20+'PyG 12 meses'!G21+'PyG 12 meses'!G22 -> 1894.0177 | I26: ='PyG 12 meses'!H19+'PyG 12 meses'!H20+'PyG 12 meses'!H21+'PyG 12 meses'!H22 -> 2503.3734 | J26: ='PyG 12 meses'!I19+'PyG 12 meses'!I20+'PyG 12 meses'!I21+'PyG 12 meses'!I22 -> 3056.3052 | K26: ='PyG 12 meses'!J19+'PyG 12 meses'!J20+'PyG 12 meses'!J21+'PyG 12 meses'!J22 -> 3756.135 | ... O26: ='PyG 12 meses'!N19+'PyG 12 meses'!N20+'PyG 12 meses'!N21+'PyG 12 meses'!N22 -> 8089.4706
A27: Pago costes fijos (€) | B27: =SUM(D27:O27) -> 17124 | C27: =0 -> 0 | D27: ='PyG 12 meses'!C35 -> 1427 | E27: ='PyG 12 meses'!D35 -> 1427 | F27: ='PyG 12 meses'!E35 -> 1427 | G27: ='PyG 12 meses'!F35 -> 1427 | H27: ='PyG 12 meses'!G35 -> 1427 | I27: ='PyG 12 meses'!H35 -> 1427 | J27: ='PyG 12 meses'!I35 -> 1427 | K27: ='PyG 12 meses'!J35 -> 1427 | ... O27: ='PyG 12 meses'!N35 -> 1427
A28: Pago inversión en Ads (€) | B28: =SUM(D28:O28) -> 71396.705 | C28: =0 -> 0 | D28: ='PyG 12 meses'!C7 -> 3000 | E28: ='PyG 12 meses'!D7 -> 3000 | F28: ='PyG 12 meses'!E7 -> 3000 | G28: ='PyG 12 meses'!F7 -> 3000 | H28: ='PyG 12 meses'!G7 -> 3600 | I28: ='PyG 12 meses'!H7 -> 4320 | J28: ='PyG 12 meses'!I7 -> 5184 | K28: ='PyG 12 meses'!J7 -> 6220.8 | ... O28: ='PyG 12 meses'!N7 -> 12899.451
A29: IVA devengado del mes (repercutido - soportado) (€) | B29: =SUM(D29:O29) -> 25494.419 | C29: =0 -> 0 | D29: ='PyG 12 meses'!C15-'PyG 12 meses'!C16-(Supuestos!$B$7)*(D17+'PyG 12 meses'!C35) -> 279.45265 | E29: ='PyG 12 meses'!D15-'PyG 12 meses'!D16-(Supuestos!$B$7)*(E17+'PyG 12 meses'!D35) -> 390.43131 | F29: ='PyG 12 meses'!E15-'PyG 12 meses'!E16-(Supuestos!$B$7)*(F17+'PyG 12 meses'!E35) -> 506.32704 | G29: ='PyG 12 meses'!F15-'PyG 12 meses'!F16-(Supuestos!$B$7)*(G17+'PyG 12 meses'!F35) -> 754.51903 | H29: ='PyG 12 meses'!G15-'PyG 12 meses'!G16-(Supuestos!$B$7)*(H17+'PyG 12 meses'!G35) -> 1073.0008 | I29: ='PyG 12 meses'!H15-'PyG 12 meses'!H16-(Supuestos!$B$7)*(I17+'PyG 12 meses'!H35) -> 1514.7944 | J29: ='PyG 12 meses'!I15-'PyG 12 meses'!I16-(Supuestos!$B$7)*(J17+'PyG 12 meses'!I35) -> 1903.3048 | K29: ='PyG 12 meses'!J15-'PyG 12 meses'!J16-(Supuestos!$B$7)*(K17+'PyG 12 meses'!J35) -> 2399.63 | ... O29: ='PyG 12 meses'!N15-'PyG 12 meses'!N16-(Supuestos!$B$7)*(O17+'PyG 12 meses'!N35) -> 5482.2254
A30: IVA liquidado (pago trimestral) (€) | B30: =SUM(D30:O30) -> 11822.575 | C30: =0 -> 0 | D30: =0 -> 0 | E30: =0 -> 0 | F30: =0 -> 0 | G30: =SUM(D29:F29) -> 1176.211 | H30: =0 -> 0 | I30: =0 -> 0 | J30: =SUM(G29:I29) -> 3342.3142 | K30: =0 -> 0 | L30: =0 -> 0 | M30: =SUM(J29:L29) -> 7304.0501 | N30: =0 -> 0 | O30: =0 -> 0
A31: Resumen de caja
A32: Caja inicial del mes (€) | B32: =SUM(D32:O32) -> -68520.034 | C32: =0 -> 0 | D32: =C35 -> -3696 | E32: =D35 -> -9264.8889 | F32: =E35 -> -7033.11 | G32: =F35 -> -6881.5972 | H32: =G35 -> -9904.176 | I32: =H35 -> -7214.4847 | J32: =I35 -> -8477.8246 | K32: =J35 -> -5957.2705 | ... O32: =N35 -> 5965.642
A33: Total entradas (€) | B33: =SUM(D33:O33) -> 325028.42 | C33: =Supuestos!$B$96 -> 25000 | D33: =D25 -> 5911.1111 | E33: =E25 -> 7585.5274 | F33: =F25 -> 8969.5102 | G33: =G25 -> 11702.057 | H33: =H25 -> 15246.493 | I33: =I25 -> 20137.197 | J33: =J25 -> 24628.692 | K33: =K25 -> 30212.754 | ... O33: =O25 -> 64972.072
A34: Total salidas (€) | B34: =SUM(D34:O34) -> 319485.01 | C34: =C15+C21 -> 28696 | D34: =D21+D22+D26+D27+D28+D30 -> 11480 | E34: =E21+E22+E26+E27+E28+E30 -> 5353.7485 | F34: =F21+F22+F26+F27+F28+F30 -> 8817.9975 | G34: =G21+G22+G26+G27+G28+G30 -> 14724.635 | H34: =H21+H22+H26+H27+H28+H30 -> 12556.802 | I34: =I21+I22+I26+I27+I28+I30 -> 21400.537 | J34: =J21+J22+J26+J27+J28+J30 -> 22108.137 | K34: =K21+K22+K26+K27+K28+K30 -> 32633.81 | ... O34: =O21+O22+O26+O27+O28+O30 -> 69090.299
A35: Caja final del mes (€) | B35: =O35 -> 1847.4152 | C35: =C32+C33-C34 -> -3696 | D35: =D32+D33-D34 -> -9264.8889 | E35: =E32+E33-E34 -> -7033.11 | F35: =F32+F33-F34 -> -6881.5972 | G35: =G32+G33-G34 -> -9904.176 | H35: =H32+H33-H34 -> -7214.4847 | I35: =I32+I33-I34 -> -8477.8246 | J35: =J32+J33-J34 -> -5957.2705 | ... O35: =O32+O33-O34 -> 1847.4152
A37: Caja mínima alcanzada (€) | B37: =MIN(D35:O35) -> -9904.176
A38: Mes de caja mínima | B38: =INDEX(D4:O4,MATCH(B37,D35:O35,0)) -> Mes 4

Sheet Punto muerto
A1: NOCTA — Punto muerto (break-even) mensual
A2: Calculado sobre el mix de ventas medio ponderado (hoja Unit Economics SKU) y los costes fijos del escenario activo.
A4: Concepto | B4: Valor | C4: Nota
A5: AOV medio ponderado (€, con IVA, escenario activo) | B5: =Supuestos!$B$119 -> 38 | C5: Coherente con la hoja PyG: el AOV incluye ~1,6 packs/SKU por pedido (Supuestos!uds_pedido).
A6: Margen de contribución medio por pedido (€, tras COGS/logística/pasarela, antes de Ads) | B6: =B5/(1+Supuestos!$B$7)-'Unit Economics SKU'!$O$19*Supuestos!$B$45-(B5*Supuestos!$B$12+Supuestos!$B$13)-'Unit Economics SKU'!$V$19-'Unit Economics SKU'!$W$19-'Unit Economics SKU'!$X$19+'Unit Economics SKU'!$Y$19*Supuestos!$B$45 -> 11.575091 | C6: Misma fórmula por pedido que usa la hoja PyG (COGS y devoluciones escalados por uds/pedido).
A7: Costes fijos mensuales totales (€) | B7: =Supuestos!$B$10+Supuestos!$B$79+Supuestos!$B$80+Supuestos!$B$106+Supuestos!$B$107+Supuestos!$B$108 -> 1427
A8: CPA máximo rentable en el primer pedido (€) | B8: =B6 -> 11.575091 | C8: Si el CPA supera el margen de contribución por pedido, cada venta nueva pierde dinero incluso antes de costes fijos.
A9: Punto muerto — pedidos/mes | B9: =B7/B6 -> 123.28197
A10: Punto muerto — ingresos/mes (€, con IVA) | B10: =B9*B5 -> 4684.7147
A11: Techo de inversión en Ads del escenario activo (€/mes) | B11: =Supuestos!$B$121 -> 18000
A13: Sensibilidad: margen de contribución mensual según CPA × AOV
A14: Para un presupuesto de Ads fijo (referencia: mes 12 del escenario activo). Pedidos = Presupuesto/CPA. Coste variable no-marketing asumido constante en € por pedido (media ponderada del mix), salvo la comisión de pago, que escala con el AOV.
A15: Presupuesto de Ads de referencia (€/mes) | B15: ='PyG 12 meses'!N7 -> 12899.451
A16: CPA \ AOV → | B16: 26 | C16: 29 | D16: 32 | E16: 35 | F16: 38 | G16: 40
A17: 8 | B17: =('PyG 12 meses'!N7/8)*((26/(1+Supuestos!$B$7))-('Unit Economics SKU'!$O$19*Supuestos!$B$45+'Unit Economics SKU'!$V$19+'Unit Economics SKU'!$W$19+'Unit Economics SKU'!$X$19-'Unit Economics SKU'!$Y$19*Supuestos!$B$45)-(26*Supuestos!$B$12+Supuestos!$B$13))-'PyG 12 meses'!N7 -> -9858.8314 | C17: =('PyG 12 meses'!N7/8)*((29/(1+Supuestos!$B$7))-('Unit Economics SKU'!$O$19*Supuestos!$B$45+'Unit Economics SKU'!$V$19+'Unit Economics SKU'!$W$19+'Unit Economics SKU'!$X$19-'Unit Economics SKU'!$Y$19*Supuestos!$B$45)-(29*Supuestos!$B$12+Supuestos!$B$13))-'PyG 12 meses'!N7 -> -5952.9762 | D17: =('PyG 12 meses'!N7/8)*((32/(1+Supuestos!$B$7))-('Unit Economics SKU'!$O$19*Supuestos!$B$45+'Unit Economics SKU'!$V$19+'Unit Economics SKU'!$W$19+'Unit Economics SKU'!$X$19-'Unit Economics SKU'!$Y$19*Supuestos!$B$45)-(32*Supuestos!$B$12+Supuestos!$B$13))-'PyG 12 meses'!N7 -> -2047.1211 | E17: =('PyG 12 meses'!N7/8)*((35/(1+Supuestos!$B$7))-('Unit Economics SKU'!$O$19*Supuestos!$B$45+'Unit Economics SKU'!$V$19+'Unit Economics SKU'!$W$19+'Unit Economics SKU'!$X$19-'Unit Economics SKU'!$Y$19*Supuestos!$B$45)-(35*Supuestos!$B$12+Supuestos!$B$13))-'PyG 12 meses'!N7 -> 1858.734 | F17: =('PyG 12 meses'!N7/8)*((38/(1+Supuestos!$B$7))-('Unit Economics SKU'!$O$19*Supuestos!$B$45+'Unit Economics SKU'!$V$19+'Unit Economics SKU'!$W$19+'Unit Economics SKU'!$X$19-'Unit Economics SKU'!$Y$19*Supuestos!$B$45)-(38*Supuestos!$B$12+Supuestos!$B$13))-'PyG 12 meses'!N7 -> 5764.5891 | G17: =('PyG 12 meses'!N7/8)*((40/(1+Supuestos!$B$7))-('Unit Economics SKU'!$O$19*Supuestos!$B$45+'Unit Economics SKU'!$V$19+'Unit Economics SKU'!$W$19+'Unit Economics SKU'!$X$19-'Unit Economics SKU'!$Y$19*Supuestos!$B$45)-(40*Supuestos!$B$12+Supuestos!$B$13))-'PyG 12 meses'!N7 -> 8368.4925
A18: 10 | B18: =('PyG 12 meses'!N7/10)*((26/(1+Supuestos!$B$7))-('Unit Economics SKU'!$O$19*Supuestos!$B$45+'Unit Economics SKU'!$V$19+'Unit Economics SKU'!$W$19+'Unit Economics SKU'!$X$19-'Unit Economics SKU'!$Y$19*Supuestos!$B$45)-(26*Supuestos!$B$12+Supuestos!$B$13))-'PyG 12 meses'!N7 -> -10466.955 | C18: =('PyG 12 meses'!N7/10)*((29/(1+Supuestos!$B$7))-('Unit Economics SKU'!$O$19*Supuestos!$B$45+'Unit Economics SKU'!$V$19+'Unit Economics SKU'!$W$19+'Unit Economics SKU'!$X$19-'Unit Economics SKU'!$Y$19*Supuestos!$B$45)-(29*Supuestos!$B$12+Supuestos!$B$13))-'PyG 12 meses'!N7 -> -7342.2712 | D18: =('PyG 12 meses'!N7/10)*((32/(1+Supuestos!$B$7))-('Unit Economics SKU'!$O$19*Supuestos!$B$45+'Unit Economics SKU'!$V$19+'Unit Economics SKU'!$W$19+'Unit Economics SKU'!$X$19-'Unit Economics SKU'!$Y$19*Supuestos!$B$45)-(32*Supuestos!$B$12+Supuestos!$B$13))-'PyG 12 meses'!N7 -> -4217.5871 | E18: =('PyG 12 meses'!N7/10)*((35/(1+Supuestos!$B$7))-('Unit Economics SKU'!$O$19*Supuestos!$B$45+'Unit Economics SKU'!$V$19+'Unit Economics SKU'!$W$19+'Unit Economics SKU'!$X$19-'Unit Economics SKU'!$Y$19*Supuestos!$B$45)-(35*Supuestos!$B$12+Supuestos!$B$13))-'PyG 12 meses'!N7 -> -1092.903 | F18: =('PyG 12 meses'!N7/10)*((38/(1+Supuestos!$B$7))-('Unit Economics SKU'!$O$19*Supuestos!$B$45+'Unit Economics SKU'!$V$19+'Unit Economics SKU'!$W$19+'Unit Economics SKU'!$X$19-'Unit Economics SKU'!$Y$19*Supuestos!$B$45)-(38*Supuestos!$B$12+Supuestos!$B$13))-'PyG 12 meses'!N7 -> 2031.7811 | G18: =('PyG 12 meses'!N7/10)*((40/(1+Supuestos!$B$7))-('Unit Economics SKU'!$O$19*Supuestos!$B$45+'Unit Economics SKU'!$V$19+'Unit Economics SKU'!$W$19+'Unit Economics SKU'!$X$19-'Unit Economics SKU'!$Y$19*Supuestos!$B$45)-(40*Supuestos!$B$12+Supuestos!$B$13))-'PyG 12 meses'!N7 -> 4114.9038
A19: 12 | B19: =('PyG 12 meses'!N7/12)*((26/(1+Supuestos!$B$7))-('Unit Economics SKU'!$O$19*Supuestos!$B$45+'Unit Economics SKU'!$V$19+'Unit Economics SKU'!$W$19+'Unit Economics SKU'!$X$19-'Unit Economics SKU'!$Y$19*Supuestos!$B$45)-(26*Supuestos!$B$12+Supuestos!$B$13))-'PyG 12 meses'!N7 -> -10872.371 | C19: =('PyG 12 meses'!N7/12)*((29/(1+Supuestos!$B$7))-('Unit Economics SKU'!$O$19*Supuestos!$B$45+'Unit Economics SKU'!$V$19+'Unit Economics SKU'!$W$19+'Unit Economics SKU'!$X$19-'Unit Economics SKU'!$Y$19*Supuestos!$B$45)-(29*Supuestos!$B$12+Supuestos!$B$13))-'PyG 12 meses'!N7 -> -8268.4678 | D19: =('PyG 12 meses'!N7/12)*((32/(1+Supuestos!$B$7))-('Unit Economics SKU'!$O$19*Supuestos!$B$45+'Unit Economics SKU'!$V$19+'Unit Economics SKU'!$W$19+'Unit Economics SKU'!$X$19-'Unit Economics SKU'!$Y$19*Supuestos!$B$45)-(32*Supuestos!$B$12+Supuestos!$B$13))-'PyG 12 meses'!N7 -> -5664.5644 | E19: =('PyG 12 meses'!N7/12)*((35/(1+Supuestos!$B$7))-('Unit Economics SKU'!$O$19*Supuestos!$B$45+'Unit Economics SKU'!$V$19+'Unit Economics SKU'!$W$19+'Unit Economics SKU'!$X$19-'Unit Economics SKU'!$Y$19*Supuestos!$B$45)-(35*Supuestos!$B$12+Supuestos!$B$13))-'PyG 12 meses'!N7 -> -3060.661 | F19: =('PyG 12 meses'!N7/12)*((38/(1+Supuestos!$B$7))-('Unit Economics SKU'!$O$19*Supuestos!$B$45+'Unit Economics SKU'!$V$19+'Unit Economics SKU'!$W$19+'Unit Economics SKU'!$X$19-'Unit Economics SKU'!$Y$19*Supuestos!$B$45)-(38*Supuestos!$B$12+Supuestos!$B$13))-'PyG 12 meses'!N7 -> -456.75755 | G19: =('PyG 12 meses'!N7/12)*((40/(1+Supuestos!$B$7))-('Unit Economics SKU'!$O$19*Supuestos!$B$45+'Unit Economics SKU'!$V$19+'Unit Economics SKU'!$W$19+'Unit Economics SKU'!$X$19-'Unit Economics SKU'!$Y$19*Supuestos!$B$45)-(40*Supuestos!$B$12+Supuestos!$B$13))-'PyG 12 meses'!N7 -> 1279.1781
A20: 14 | B20: =('PyG 12 meses'!N7/14)*((26/(1+Supuestos!$B$7))-('Unit Economics SKU'!$O$19*Supuestos!$B$45+'Unit Economics SKU'!$V$19+'Unit Economics SKU'!$W$19+'Unit Economics SKU'!$X$19-'Unit Economics SKU'!$Y$19*Supuestos!$B$45)-(26*Supuestos!$B$12+Supuestos!$B$13))-'PyG 12 meses'!N7 -> -11161.954 | C20: =('PyG 12 meses'!N7/14)*((29/(1+Supuestos!$B$7))-('Unit Economics SKU'!$O$19*Supuestos!$B$45+'Unit Economics SKU'!$V$19+'Unit Economics SKU'!$W$19+'Unit Economics SKU'!$X$19-'Unit Economics SKU'!$Y$19*Supuestos!$B$45)-(29*Supuestos!$B$12+Supuestos!$B$13))-'PyG 12 meses'!N7 -> -8930.0368 | D20: =('PyG 12 meses'!N7/14)*((32/(1+Supuestos!$B$7))-('Unit Economics SKU'!$O$19*Supuestos!$B$45+'Unit Economics SKU'!$V$19+'Unit Economics SKU'!$W$19+'Unit Economics SKU'!$X$19-'Unit Economics SKU'!$Y$19*Supuestos!$B$45)-(32*Supuestos!$B$12+Supuestos!$B$13))-'PyG 12 meses'!N7 -> -6698.1196 | E20: =('PyG 12 meses'!N7/14)*((35/(1+Supuestos!$B$7))-('Unit Economics SKU'!$O$19*Supuestos!$B$45+'Unit Economics SKU'!$V$19+'Unit Economics SKU'!$W$19+'Unit Economics SKU'!$X$19-'Unit Economics SKU'!$Y$19*Supuestos!$B$45)-(35*Supuestos!$B$12+Supuestos!$B$13))-'PyG 12 meses'!N7 -> -4466.2024 | F20: =('PyG 12 meses'!N7/14)*((38/(1+Supuestos!$B$7))-('Unit Economics SKU'!$O$19*Supuestos!$B$45+'Unit Economics SKU'!$V$19+'Unit Economics SKU'!$W$19+'Unit Economics SKU'!$X$19-'Unit Economics SKU'!$Y$19*Supuestos!$B$45)-(38*Supuestos!$B$12+Supuestos!$B$13))-'PyG 12 meses'!N7 -> -2234.2852 | G20: =('PyG 12 meses'!N7/14)*((40/(1+Supuestos!$B$7))-('Unit Economics SKU'!$O$19*Supuestos!$B$45+'Unit Economics SKU'!$V$19+'Unit Economics SKU'!$W$19+'Unit Economics SKU'!$X$19-'Unit Economics SKU'!$Y$19*Supuestos!$B$45)-(40*Supuestos!$B$12+Supuestos!$B$13))-'PyG 12 meses'!N7 -> -746.34037
A21: 16 | B21: =('PyG 12 meses'!N7/16)*((26/(1+Supuestos!$B$7))-('Unit Economics SKU'!$O$19*Supuestos!$B$45+'Unit Economics SKU'!$V$19+'Unit Economics SKU'!$W$19+'Unit Economics SKU'!$X$19-'Unit Economics SKU'!$Y$19*Supuestos!$B$45)-(26*Supuestos!$B$12+Supuestos!$B$13))-'PyG 12 meses'!N7 -> -11379.141 | C21: =('PyG 12 meses'!N7/16)*((29/(1+Supuestos!$B$7))-('Unit Economics SKU'!$O$19*Supuestos!$B$45+'Unit Economics SKU'!$V$19+'Unit Economics SKU'!$W$19+'Unit Economics SKU'!$X$19-'Unit Economics SKU'!$Y$19*Supuestos!$B$45)-(29*Supuestos!$B$12+Supuestos!$B$13))-'PyG 12 meses'!N7 -> -9426.2136 | D21: =('PyG 12 meses'!N7/16)*((32/(1+Supuestos!$B$7))-('Unit Economics SKU'!$O$19*Supuestos!$B$45+'Unit Economics SKU'!$V$19+'Unit Economics SKU'!$W$19+'Unit Economics SKU'!$X$19-'Unit Economics SKU'!$Y$19*Supuestos!$B$45)-(32*Supuestos!$B$12+Supuestos!$B$13))-'PyG 12 meses'!N7 -> -7473.286 | E21: =('PyG 12 meses'!N7/16)*((35/(1+Supuestos!$B$7))-('Unit Economics SKU'!$O$19*Supuestos!$B$45+'Unit Economics SKU'!$V$19+'Unit Economics SKU'!$W$19+'Unit Economics SKU'!$X$19-'Unit Economics SKU'!$Y$19*Supuestos!$B$45)-(35*Supuestos!$B$12+Supuestos!$B$13))-'PyG 12 meses'!N7 -> -5520.3584 | F21: =('PyG 12 meses'!N7/16)*((38/(1+Supuestos!$B$7))-('Unit Economics SKU'!$O$19*Supuestos!$B$45+'Unit Economics SKU'!$V$19+'Unit Economics SKU'!$W$19+'Unit Economics SKU'!$X$19-'Unit Economics SKU'!$Y$19*Supuestos!$B$45)-(38*Supuestos!$B$12+Supuestos!$B$13))-'PyG 12 meses'!N7 -> -3567.4309 | G21: =('PyG 12 meses'!N7/16)*((40/(1+Supuestos!$B$7))-('Unit Economics SKU'!$O$19*Supuestos!$B$45+'Unit Economics SKU'!$V$19+'Unit Economics SKU'!$W$19+'Unit Economics SKU'!$X$19-'Unit Economics SKU'!$Y$19*Supuestos!$B$45)-(40*Supuestos!$B$12+Supuestos!$B$13))-'PyG 12 meses'!N7 -> -2265.4792
A22: 18 | B22: =('PyG 12 meses'!N7/18)*((26/(1+Supuestos!$B$7))-('Unit Economics SKU'!$O$19*Supuestos!$B$45+'Unit Economics SKU'!$V$19+'Unit Economics SKU'!$W$19+'Unit Economics SKU'!$X$19-'Unit Economics SKU'!$Y$19*Supuestos!$B$45)-(26*Supuestos!$B$12+Supuestos!$B$13))-'PyG 12 meses'!N7 -> -11548.064 | C22: =('PyG 12 meses'!N7/18)*((29/(1+Supuestos!$B$7))-('Unit Economics SKU'!$O$19*Supuestos!$B$45+'Unit Economics SKU'!$V$19+'Unit Economics SKU'!$W$19+'Unit Economics SKU'!$X$19-'Unit Economics SKU'!$Y$19*Supuestos!$B$45)-(29*Supuestos!$B$12+Supuestos!$B$13))-'PyG 12 meses'!N7 -> -9812.1288 | D22: =('PyG 12 meses'!N7/18)*((32/(1+Supuestos!$B$7))-('Unit Economics SKU'!$O$19*Supuestos!$B$45+'Unit Economics SKU'!$V$19+'Unit Economics SKU'!$W$19+'Unit Economics SKU'!$X$19-'Unit Economics SKU'!$Y$19*Supuestos!$B$45)-(32*Supuestos!$B$12+Supuestos!$B$13))-'PyG 12 meses'!N7 -> -8076.1932 | E22: =('PyG 12 meses'!N7/18)*((35/(1+Supuestos!$B$7))-('Unit Economics SKU'!$O$19*Supuestos!$B$45+'Unit Economics SKU'!$V$19+'Unit Economics SKU'!$W$19+'Unit Economics SKU'!$X$19-'Unit Economics SKU'!$Y$19*Supuestos!$B$45)-(35*Supuestos!$B$12+Supuestos!$B$13))-'PyG 12 meses'!N7 -> -6340.2576 | F22: =('PyG 12 meses'!N7/18)*((38/(1+Supuestos!$B$7))-('Unit Economics SKU'!$O$19*Supuestos!$B$45+'Unit Economics SKU'!$V$19+'Unit Economics SKU'!$W$19+'Unit Economics SKU'!$X$19-'Unit Economics SKU'!$Y$19*Supuestos!$B$45)-(38*Supuestos!$B$12+Supuestos!$B$13))-'PyG 12 meses'!N7 -> -4604.322 | G22: =('PyG 12 meses'!N7/18)*((40/(1+Supuestos!$B$7))-('Unit Economics SKU'!$O$19*Supuestos!$B$45+'Unit Economics SKU'!$V$19+'Unit Economics SKU'!$W$19+'Unit Economics SKU'!$X$19-'Unit Economics SKU'!$Y$19*Supuestos!$B$45)-(40*Supuestos!$B$12+Supuestos!$B$13))-'PyG 12 meses'!N7 -> -3447.0316
